Workbook

Sheet Madre_Coperture
A1: MULTIPLATORE A SCALARE - 15 EVENTI
A2: Under 3.5=1.32 | Over 3.5=3.0 | Exchange=2.75 | Target=45 | Bonus su 5+ eventi | PRODOTTO (non somma)
A4: QUOTE EVENTI
A5: Evento | B5: Under 3,5 | C5: Over 3,5
A6: E1 | B6: 1.32 | C6: 3
A7: E2 | B7: 1.32 | C7: 3
A8: E3 | B8: 1.32 | C8: 3
A9: E4 | B9: 1.32 | C9: 3
A10: E5 | B10: 1.32 | C10: 3
A11: E6 | B11: 1.32 | C11: 3
A12: E7 | B12: 1.32 | C12: 3
A13: E8 | B13: 1.32 | C13: 3
A14: E9 | B14: 1.32 | C14: 3
A15: E10 | B15: 1.32 | C15: 3
A16: E11 | B16: 1.32 | C16: 3
A17: E12 | B17: 1.32 | C17: 3
... A20: E15 | B20: 1.32 | C20: 3
A23: MADRE INIZIALE (15 eventi UNDER) + COPERTURE
A24: Step | B24: N_pendente | C24: Prodotto_raw | D24: Bonus_% | E24: Molt._finale | F24: Stake | G24: Spesa_cum | H24: Lordo | I24: Netto
A25: Madre S0 | B25: 15 | C25: =1.32^B25 | D25: 89.8 | E25: =C25*(1+D25/100) | F25: 2 | G25: =F25 | H25: =F25*E25 | I25: =H25-G25
A26: Coper. 1 | B26: 14 | C26: =1.32^B26 | D26: 79.1 | E26: =C26*(1+D26/100) | F26: =ROUNDUP((G25+45)/(E26-1)/0.5,0)*0.5 | G26: =G25+F26 | H26: =F26*E26 | I26: =H26-G26
A27: Coper. 2 | B27: 13 | C27: =1.32^B27 | D27: 68.9 | E27: =C27*(1+D27/100) | F27: =ROUNDUP((G26+45)/(E27-1)/0.5,0)*0.5 | G27: =G26+F27 | H27: =F27*E27 | I27: =H27-G27
A28: Coper. 3 | B28: 12 | C28: =1.32^B28 | D28: 59.4 | E28: =C28*(1+D28/100) | F28: =ROUNDUP((G27+45)/(E28-1)/0.5,0)*0.5 | G28: =G27+F28 | H28: =F28*E28 | I28: =H28-G28
A29: Coper. 4 | B29: 11 | C29: =1.32^B29 | D29: 50.4 | E29: =C29*(1+D29/100) | F29: =ROUNDUP((G28+45)/(E29-1)/0.5,0)*0.5 | G29: =G28+F29 | H29: =F29*E29 | I29: =H29-G29
A30: Coper. 5 | B30: 10 | C30: =1.32^B30 | D30: 41.9 | E30: =C30*(1+D30/100) | F30: =ROUNDUP((G29+45)/(E30-1)/0.5,0)*0.5 | G30: =G29+F30 | H30: =F30*E30 | I30: =H30-G30
A31: Coper. 6 | B31: 9 | C31: =1.32^B31 | D31: 33.8 | E31: =C31*(1+D31/100) | F31: =ROUNDUP((G30+45)/(E31-1)/0.5,0)*0.5 | G31: =G30+F31 | H31: =F31*E31 | I31: =H31-G31
A32: Coper. 7 | B32: 8 | C32: =1.32^B32 | D32: 26.2 | E32: =C32*(1+D32/100) | F32: =ROUNDUP((G31+45)/(E32-1)/0.5,0)*0.5 | G32: =G31+F32 | H32: =F32*E32 | I32: =H32-G32
A33: Coper. 8 | B33: 7 | C33: =1.32^B33 | D33: 19.1 | E33: =C33*(1+D33/100) | F33: =ROUNDUP((G32+45)/(E33-1)/0.5,0)*0.5 | G33: =G32+F33 | H33: =F33*E33 | I33: =H33-G33
A34: Coper. 9 | B34: 6 | C34: =1.32^B34 | D34: 12.4 | E34: =C34*(1+D34/100) | F34: =ROUNDUP((G33+45)/(E34-1)/0.5,0)*0.5 | G34: =G33+F34 | H34: =F34*E34 | I34: =H34-G34
A35: Coper. 10 | B35: 5 | C35: =1.32^B35 | D35: 6 | E35: =C35*(1+D35/100) | F35: =ROUNDUP((G34+45)/(E35-1)/0.5,0)*0.5 | G35: =G34+F35 | H35: =F35*E35 | I35: =H35-G35
A36: Coper. 11 | B36: 4 | C36: =1.32^B36 | D36: 0 | E36: =C36*(1+D36/100) | F36: =ROUNDUP((G35+45)/(E36-1)/0.5,0)*0.5 | G36: =G35+F36 | H36: =F36*E36 | I36: =H36-G36
A37: Coper. 12 | B37: 3 | C37: =1.32^B37 | D37: 0 | E37: =C37*(1+D37/100) | F37: =ROUNDUP((G36+45)/(E37-1)/0.5,0)*0.5 | G37: =G36+F37 | H37: =F37*E37 | I37: =H37-G37
... A39: Coper. 14 | B39: 1 | C39: =1.32^B39 | D39: 0 | E39: =C39*(1+D39/100) | F39: =ROUNDUP((G38+45)/(E39-1)/0.5,0)*0.5 | G39: =G38+F39 | H39: =F39*E39 | I39: =H39-G39
A40: LOCK Exchange | B40: 0 | C40: 2.75 | D40: 0 | E40: 2.75 | F40: =ROUNDUP((G39+45)/(E40-1)/0.5,0)*0.5 | G40: =G39+F40 | H40: =F40*E40 | I40: =H40-G40
A42: RIEPILOGO
A43: Spesa Madre S0 | B43: =F25
A44: Spesa Totale Ciclo (fino a lock) | B44: =G40
A45: Vincita Madre (tutti Under) | B45: =H25
A46: Vincita Copertura 1 (1 errore) | B46: =H26
A47: Vincita Lock Exchange | B47: =H40
...

Sheet Tabelle
A1: TABELLE BONUS & ASSICURAZIONE
A3: TABELLA BONUS MULTIPLA
A4: N Eventi | B4: % BONUS | C4: Molt. Raw (1.32^N) | D4: Molt. Finale | E4: Formula
A5: 5 | B5: 6 | C5: =1.32^A5 | D5: =C5*(1+B5/100) | E5: 1.32^5 x (1 + 6.0%)
A6: 6 | B6: 12.4 | C6: =1.32^A6 | D6: =C6*(1+B6/100) | E6: 1.32^6 x (1 + 12.4%)
A7: 7 | B7: 19.1 | C7: =1.32^A7 | D7: =C7*(1+B7/100) | E7: 1.32^7 x (1 + 19.1%)
A8: 8 | B8: 26.2 | C8: =1.32^A8 | D8: =C8*(1+B8/100) | E8: 1.32^8 x (1 + 26.2%)
A9: 9 | B9: 33.8 | C9: =1.32^A9 | D9: =C9*(1+B9/100) | E9: 1.32^9 x (1 + 33.8%)
A10: 10 | B10: 41.9 | C10: =1.32^A10 | D10: =C10*(1+B10/100) | E10: 1.32^10 x (1 + 41.9%)
A11: 11 | B11: 50.4 | C11: =1.32^A11 | D11: =C11*(1+B11/100) | E11: 1.32^11 x (1 + 50.4%)
A12: 12 | B12: 59.4 | C12: =1.32^A12 | D12: =C12*(1+B12/100) | E12: 1.32^12 x (1 + 59.4%)
A13: 13 | B13: 68.9 | C13: =1.32^A13 | D13: =C13*(1+B13/100) | E13: 1.32^13 x (1 + 68.9%)
A14: 14 | B14: 79.1 | C14: =1.32^A14 | D14: =C14*(1+B14/100) | E14: 1.32^14 x (1 + 79.1%)
A15: 15 | B15: 89.8 | C15: =1.32^A15 | D15: =C15*(1+B15/100) | E15: 1.32^15 x (1 + 89.8%)
A16: 16 | B16: 101.2 | C16: =1.32^A16 | D16: =C16*(1+B16/100) | E16: 1.32^16 x (1 + 101.2%)
... A30: 30 | B30: 354.9 | C30: =1.32^A30 | D30: =C30*(1+B30/100) | E30: 1.32^30 x (1 + 354.9%)
A36: TABELLA ASSICURAZIONE (N >= 4)
A37: N Eventi | B37: 1 Errore | C37: 2 Errori | D37: 3 Errori | E37: Rimborso Max
A38: 4 | B38: 30 | C38: 10 | D38: 0 | E38: 50
A39: 5 | B39: 60 | C39: 30 | D39: 10 | E39: 50
A40: 6 | B40: 80 | C40: 60 | D40: 30 | E40: 50
A41: 7 | B41: 100 | C41: 80 | D41: 60 | E41: 50
A44: QUOTA MINIMA: 1.25

Sheet Simulazione
A1: SIMULAZIONE - Over al 4 evento (15 eventi)
A2: M1-M3 Under (Madre attiva), M4 Over (Madre muore), C4 attiva per M5-M15, poi Lock
A4: Step | B4: Evento | C4: Esito | D4: Ticket Attivo | E4: N_pending | F4: Raw | G4: Finale | H4: Stake | I4: Spesa_cum | J4: Lordo | K4: Netto
A5: S0/M1 | B5: M1 | C5: Under | D5: Madre | E5: 15 | F5: =1.32^15 | G5: =F5*(1+89.8/100) | H5: 2 | I5: 2 | J5: =H5*G5 | K5: =J5-I5
A6: S0/M2 | B6: M2 | C6: Under | D6: Madre | E6: 14 | F6: =1.32^14 | G6: =F6*(1+79.1/100) | H6: =ROUNDUP((I5+45)/(G6-1)/0.5,0)*0.5 | I6: =I5+H6 | J6: =H6*G6 | K6: =J6-I6
A7: S0/M3 | B7: M3 | C7: Under | D7: Madre | E7: 13 | F7: =1.32^13 | G7: =F7*(1+68.9/100) | H7: =ROUNDUP((I6+45)/(G7-1)/0.5,0)*0.5 | I7: =I6+H7 | J7: =H7*G7 | K7: =J7-I7
A8: M4 | B8: M4 | C8: OVER | D8: S0->C4 | E8: 11 | F8: =1.32^11 | G8: =F8*(1+50.4/100) | H8: =ROUNDUP((I7+45)/(G8-1)/0.5,0)*0.5 | I8: =I7+H8 | J8: =H8*G8 | K8: =J8-I8
A9: C4/M5 | B9: M5 | C9: Under | D9: C4 | E9: 10 | F9: =1.32^10 | G9: =F9*(1+41.9/100) | H9: =ROUNDUP((I8+45)/(G9-1)/0.5,0)*0.5 | I9: =I8+H9 | J9: =H9*G9 | K9: =J9-I9
A10: C4/M6 | B10: M6 | C10: Under | D10: C4 | E10: 9 | F10: =1.32^9 | G10: =F10*(1+33.8/100) | H10: =ROUNDUP((I9+45)/(G10-1)/0.5,0)*0.5 | I10: =I9+H10 | J10: =H10*G10 | K10: =J10-I10
A11: C4/M7 | B11: M7 | C11: Under | D11: C4 | E11: 8 | F11: =1.32^8 | G11: =F11*(1+26.2/100) | H11: =ROUNDUP((I10+45)/(G11-1)/0.5,0)*0.5 | I11: =I10+H11 | J11: =H11*G11 | K11: =J11-I11
A12: C4/M8 | B12: M8 | C12: Under | D12: C4 | E12: 7 | F12: =1.32^7 | G12: =F12*(1+19.1/100) | H12: =ROUNDUP((I11+45)/(G12-1)/0.5,0)*0.5 | I12: =I11+H12 | J12: =H12*G12 | K12: =J12-I12
A13: C4/M9 | B13: M9 | C13: Under | D13: C4 | E13: 6 | F13: =1.32^6 | G13: =F13*(1+12.4/100) | H13: =ROUNDUP((I12+45)/(G13-1)/0.5,0)*0.5 | I13: =I12+H13 | J13: =H13*G13 | K13: =J13-I13
A14: Lock | B14: Exchange | C14: LOCK | D14: Exchange | E14: 0 | F14: 2.75 | G14: 2.75 | H14: =ROUNDUP((I13+45)/(G14-1)/0.5,0)*0.5 | I14: =I13+H14 | J14: =H14*G14 | K14: =J14-I14
A16: RISULTATO
A17: Costo totale ciclo (fino a lock) | B17: =I14
A18: Vincita Lock Exchange | B18: =J14
A19: Netto Lock | B19: =K14
A20: ROI Lock | B20: =K14/I14

Sheet Assicurazione
A1: ASSICURAZIONE (separata dal calcolo coperture)
A2: Non entra in quote/bonus/stake. Solo rimborso passivo su ticket persi ammissibili.
A4: N Eventi | B4: 1 Errore | C4: 2 Errori | D4: 3 Errori | E4: Rimborso Max
A5: 4 | B5: 30 | C5: 10 | D5: 0 | E5: 50
A6: 5 | B6: 60 | C6: 30 | D6: 10 | E6: 50
A7: 6 | B7: 80 | C7: 60 | D7: 30 | E7: 50
A8: 7 | B8: 100 | C8: 80 | D8: 60 | E8: 50
A11: SCENARIO: C4 attiva (N_int=12, N_slip=11)
A12: Parametro | B12: Valore | C12: Note
A13: N_internal (confermate+pending) | B13: 12 | C13: 4 confermate (M1-M4) + 11 pending -> tabella 7+
A14: N_slip (solo pending) | B14: 11 | C14: Per bonus: tabella_bonus[11]=50.4%
A15: Stake C4 (da Madre_Coperture) | B15: ='Madre_Coperture'!F29 | C15: Riga Coper.4 del foglio Madre_Coperture
A16: Rimborso 1 errore (100%) | B16: =MIN(B15,50)*1.00
A17: Rimborso 2 errori (80%) | B17: =MIN(B15,50)*0.80
A18: Rimborso 3 errori (60%) | B18: =MIN(B15,50)*0.60
A19: Rimborso 4+ errori (0%) | B19: =0

Sheet Tutte_Situazioni
A1: TUTTE LE SITUAZIONI - 15 EVENTI
A2: Solo 1 ticket attivo alla volta. Spesa/vincita da foglio Madre_Coperture.
A4: Scenario | B4: Errori | C4: Posizione | D4: Stato | E4: Spesa | F4: Vincita | G4: Netto | H4: ROI
A5: E0 | B5: 0 | C5: Nessuno | D5: Madre vince | E5: ='Madre_Coperture'!G25 | F5: ='Madre_Coperture'!H25 | G5: ='Madre_Coperture'!I25 | H5: =IF(E5=0,0,G5/E5)
A6: E1(k=1) | B6: 1 | C6: M1 | D6: C1 attiva | E6: ='Madre_Coperture'!G26 | F6: ='Madre_Coperture'!H26 | G6: ='Madre_Coperture'!I26 | H6: =IF(E6=0,0,G6/E6)
A7: E1(k=2) | B7: 1 | C7: M2 | D7: C2 attiva | E7: ='Madre_Coperture'!G27 | F7: ='Madre_Coperture'!H27 | G7: ='Madre_Coperture'!I27 | H7: =IF(E7=0,0,G7/E7)
A8: E1(k=3) | B8: 1 | C8: M3 | D8: C3 attiva | E8: ='Madre_Coperture'!G28 | F8: ='Madre_Coperture'!H28 | G8: ='Madre_Coperture'!I28 | H8: =IF(E8=0,0,G8/E8)
A9: E1(k=4) | B9: 1 | C9: M4 | D9: C4 attiva | E9: ='Madre_Coperture'!G29 | F9: ='Madre_Coperture'!H29 | G9: ='Madre_Coperture'!I29 | H9: =IF(E9=0,0,G9/E9)
A10: E1(k=5) | B10: 1 | C10: M5 | D10: C5 attiva | E10: ='Madre_Coperture'!G30 | F10: ='Madre_Coperture'!H30 | G10: ='Madre_Coperture'!I30 | H10: =IF(E10=0,0,G10/E10)
A11: E1(k=6) | B11: 1 | C11: M6 | D11: C6 attiva | E11: ='Madre_Coperture'!G31 | F11: ='Madre_Coperture'!H31 | G11: ='Madre_Coperture'!I31 | H11: =IF(E11=0,0,G11/E11)
A12: E1(k=7) | B12: 1 | C12: M7 | D12: C7 attiva | E12: ='Madre_Coperture'!G32 | F12: ='Madre_Coperture'!H32 | G12: ='Madre_Coperture'!I32 | H12: =IF(E12=0,0,G12/E12)
A13: E1(k=8) | B13: 1 | C13: M8 | D13: C8 attiva | E13: ='Madre_Coperture'!G33 | F13: ='Madre_Coperture'!H33 | G13: ='Madre_Coperture'!I33 | H13: =IF(E13=0,0,G13/E13)
A14: E1(k=9) | B14: 1 | C14: M9 | D14: C9 attiva | E14: ='Madre_Coperture'!G34 | F14: ='Madre_Coperture'!H34 | G14: ='Madre_Coperture'!I34 | H14: =IF(E14=0,0,G14/E14)
A15: E1(k=10) | B15: 1 | C15: M10 | D15: C10 attiva | E15: ='Madre_Coperture'!G35 | F15: ='Madre_Coperture'!H35 | G15: ='Madre_Coperture'!I35 | H15: =IF(E15=0,0,G15/E15)
A16: E1(k=11) | B16: 1 | C16: M11 | D16: C11 attiva | E16: ='Madre_Coperture'!G36 | F16: ='Madre_Coperture'!H36 | G16: ='Madre_Coperture'!I36 | H16: =IF(E16=0,0,G16/E16)
... A19: E1(k=14) | B19: 1 | C19: M14 | D19: C14 attiva | E19: ='Madre_Coperture'!G39 | F19: ='Madre_Coperture'!H39 | G19: ='Madre_Coperture'!I39 | H19: =IF(E19=0,0,G19/E19)
A20: E1(k=15) | B20: 1 | C20: M15 | D20: Lock
A21: E2(1,2) | B21: 2 | C21: M1,M2 | D21: C2 attiva
A22: E2(1,5) | B22: 2 | C22: M1,M5 | D22: C5 attiva
A23: E2(4,8) | B23: 2 | C23: M4,M8 | D23: C8 attiva
A24: E2(7,14) | B24: 2 | C24: M7,M14 | D24: C14 attiva
A25: E3(1,2,3) | B25: 3 | C25: M1-M3 | D25: C3 attiva
A26: E3(1,4,8) | B26: 3 | C26: M1,M4,M8 | D26: C8 attiva
A27: E3(5,9,13) | B27: 3 | C27: M5,M9,M13 | D27: C13 attiva
A28: E4(1-4) | B28: 4 | C28: M1-M4 | D28: C4 attiva
A29: E5(1-5) | B29: 5 | C29: M1-M5 | D29: C5 attiva
A30: E15 | B30: 15 | C30: Tutti | D30: Lock
A32: SINTESI
A33: E0 Madre: alta vincita, bassa prob.
A34: E1: la copertura ripristina il target se vince.
A35: E2+: catene profonde, stake crescenti, stop-loss.

Sheet Formule
A1: SCHEMA FORMULE
A3: Parametro | B3: Formula | C3: Note
A4: N_slip | B4: solo eventi PENDING | C4: per quote e bonus
A5: raw | B5: 1.32^N_slip | C5: PRODOTTO, non somma
A6: bonus_pct | B6: Tabelle[N_slip] | C6: lookup 5-30 eventi
A7: finale | B7: raw * (1 + bonus/100) | C7: moltiplicatore finale
A8: stake_neutra | B8: (speso + T) / (finale - 1) | C8: arrotondata a 0.50 per eccesso
A9: stake | B9: alfa * stake_neutra (alfa>=1 primi step) | C9: mai sotto la neutra
A10: spesa_cum | B10: speso_prev + stake | C10: costo effettivo
A11: lordo | B11: stake * finale | C11: vincita ticket
A12: netto | B12: lordo - spesa_cum | C12: profitto ciclo
A13: N_internal | B13: confermate + pending | C13: SOLO per assicurazione, fuori dal computo
